Workbook
Name _1_12월배송율최종: #REF!
Name _2월배송율: #REF!
Name _2鱭迌ǒꐶ䧮䬢_빼菺쑅怀㊅蒵鬰伏ꐁ_ﻰ뿏哜痆䈜琼䁒鲥†_舂₀_Ȉኻ撁_⼃萀駥끾㏹_ﵒ_萀件쨽_⼏䟵₂냴憼꿍깧_xdbac_歳й⼍饳砺븫ﲻ㌸랻떎嫃缊_輿鷄쿊____鬣㙐_ᅿ㞧걶倃꾮: [1]!conb90
Name a: '[1]9-1차이내역'!#REF!
Name as: '[1]9-1차이내역'!#REF!
Name asdf: '[1]9-1차이내역'!#REF!
Name bcrclcl100rt: '[1]9-1차이내역'!#REF!
Name bcrclcl100rtrkrk: '[1]9-1차이내역'!#REF!
Name BLPICKUP: #REF!
Name BL인수: #REF!
Name conb1: [1]!conb1
Name conb10: [1]!conb10
Name conb100: [1]!conb100
Name conb101: [1]!conb101
Name conb102: [1]!conb102
Name conb103: [1]!conb103
Name conb104: [1]!conb104
Name conb105: [1]!conb105
Name conb106: [1]!conb106
Name conb107: [1]!conb107
Name conb108: [1]!conb108
Name conb109: [1]!conb109
Name conb11: [1]!conb11
Name conb110: [1]!conb110
Name conb111: [1]!conb111
Name conb112: [1]!conb112
Name conb113: [1]!conb113
Name conb114: [1]!conb114
Name conb115: [1]!conb115
Name conb116: [1]!conb116
Name conb117: [1]!conb117
Name conb118: [1]!conb118
Name conb119: [1]!conb119
Name conb12: [1]!conb12
Name conb120: [1]!conb120
Name conb121: [1]!conb121
Name conb13: [1]!conb13
Name conb14: [1]!conb14
Name conb15: [1]!conb15
Name conb16: [1]!conb16
Name conb17: [1]!conb17
Name conb18: [1]!conb18
Name conb19: [1]!conb19
Name conb2: [1]!conb2
Name conb20: [1]!conb20
Name conb21: [1]!conb21
Name conb22: [1]!conb22
Name conb23: [1]!conb23
Name conb24: [1]!conb24
Name conb25: [1]!conb25
Name conb26: [1]!conb26
Name conb27: [1]!conb27
Name conb28: [1]!conb28
Name conb29: [1]!conb29
Name conb3: [1]!conb3
Name conb30: [1]!conb30
Name conb31: [1]!conb31
Name conb33: [1]!conb33
Name conb34: [1]!conb34
Name conb36: [1]!conb36

Sheet Supplier Evaluation
B1: SUPPLIER EVALUATION
B3: Supplier Name:
B4: Supply of Product or Service:
B5: Annual transaction amount:
B6: Assessment Period:
B8: [Supplier Assessment]
B9: 구 분 | C9: 평가항목 | D9: 평가 세부 구분 | E9: 배점 | F9: 점 수 | G9: 비 고
A11: 1 | B11: Supplier Capability | C11: Financial Stability | D11: 재무현황 개선도 (전년도 대비) | E11: =VLOOKUP($A11,'Supplier Assessment'!$H$8:$J$1000,3,FALSE) -> 5 | F11: =VLOOKUP($A11,'Supplier Assessment'!$H$8:$J$1000,2,FALSE) -> 0
A12: 2 | C12: Company Certification | D12: ISO 인증 여부 | E12: =VLOOKUP($A12,'Supplier Assessment'!$H$8:$J$1000,3,FALSE) -> 5 | F12: =VLOOKUP($A12,'Supplier Assessment'!$H$8:$J$1000,2,FALSE) -> 0
A13: 3 | C13: Account Manger | D13: 전담 조직 구성 | E13: =VLOOKUP($A13,'Supplier Assessment'!$H$8:$J$1000,3,FALSE) -> 5 | F13: =VLOOKUP($A13,'Supplier Assessment'!$H$8:$J$1000,2,FALSE) -> 0
A14: 4 | C14: Historical Status | D14: 당사와의 거래이력 | E14: =VLOOKUP($A14,'Supplier Assessment'!$H$8:$J$1000,3,FALSE) -> 5 | F14: =VLOOKUP($A14,'Supplier Assessment'!$H$8:$J$1000,2,FALSE) -> 0
C15: 소 계 | E15: =SUM(E11:E14) -> 20 | F15: =SUM(F11:F14) -> 0
A16: 5 | B16: Supplier Performance | C16: Price | D16: 원가절감율 | E16: =VLOOKUP($A16,'Supplier Assessment'!$H$8:$J$1000,3,FALSE) -> 20 | F16: =VLOOKUP($A16,'Supplier Assessment'!$H$8:$J$1000,2,FALSE) -> 0
A17: 6 | C17: Quality | D17: 품질관리 | E17: =VLOOKUP($A17,'Supplier Assessment'!$H$8:$J$1000,3,FALSE) -> 5 | F17: =VLOOKUP($A17,'Supplier Assessment'!$H$8:$J$1000,2,FALSE) -> 0
A18: 7 | D18: CLAIM 발생 빈도 | E18: =VLOOKUP($A18,'Supplier Assessment'!$H$8:$J$1000,3,FALSE) -> 5 | F18: =VLOOKUP($A18,'Supplier Assessment'!$H$8:$J$1000,2,FALSE) -> 0
A19: 8 | C19: Service Level | D19: CLAIM 사후관리 | E19: =VLOOKUP($A19,'Supplier Assessment'!$H$8:$J$1000,3,FALSE) -> 5 | F19: =VLOOKUP($A19,'Supplier Assessment'!$H$8:$J$1000,2,FALSE) -> 0
A20: 9 | D20: 견적불가 및 지연 | E20: =VLOOKUP($A20,'Supplier Assessment'!$H$8:$J$1000,3,FALSE) -> 5 | F20: =VLOOKUP($A20,'Supplier Assessment'!$H$8:$J$1000,2,FALSE) -> 0
A21: 10 | D21: 단종 및 SPEC 불명확 자재 대응도 | E21: =VLOOKUP($A21,'Supplier Assessment'!$H$8:$J$1000,3,FALSE) -> 5 | F21: =VLOOKUP($A21,'Supplier Assessment'!$H$8:$J$1000,2,FALSE) -> 0
A22: 11 | D22: 긴급/소량, 발주 취소 대응 처리건 | E22: =VLOOKUP($A22,'Supplier Assessment'!$H$8:$J$1000,3,FALSE) -> 10 | F22: =VLOOKUP($A22,'Supplier Assessment'!$H$8:$J$1000,2,FALSE) -> 0
A23: 12 | D23: 문서처리(VBS, RFQ, 거래명세서) 기한내 불이행율 | E23: =VLOOKUP($A23,'Supplier Assessment'!$H$8:$J$1000,3,FALSE) -> 10 | F23: =VLOOKUP($A23,'Supplier Assessment'!$H$8:$J$1000,2,FALSE) -> 0
A24: 13 | C24: Delivery & Response | D24: 납기관리 | E24: =VLOOKUP($A24,'Supplier Assessment'!$H$8:$J$1000,3,FALSE) -> 5 | F24: =VLOOKUP($A24,'Supplier Assessment'!$H$8:$J$1000,2,FALSE) -> 0
A25: 14 | D25: 납기준수 | E25: =VLOOKUP($A25,'Supplier Assessment'!$H$8:$J$1000,3,FALSE) -> 10 | F25: =VLOOKUP($A25,'Supplier Assessment'!$H$8:$J$1000,2,FALSE) -> 0
C26: 소 계 | E26: =SUM(E16:E25) -> 80 | F26: =SUM(F16:F25) -> 0
B27: 합 계 | E27: 100 | F27: 100 | G27: =IF(F27>=80,"Preferred",IF(F27>=60,"Qualified",IF(F27>=40,"Marginal","Unqualified"))) -> Preferred
B29: [HSSE]
B30: 구 분 | C30: 평가항목 | E30: 배점 | F30: 점 수 | G30: 비 고
B32: HSSE | C32: 협력업체 안전∙보건관리 | E32: 100 | F32: =HSE!Z15 -> 100 | G32: =IF(F32>=80,"Preferred",IF(F32>=60,"Qualified",IF(F32>=40,"Marginal","Unqualified"))) -> Preferred

Sheet Process Monitoring
C2: Procurement Process Monitoring & Management Checklist
C4: Check list | H4: Description | I4: Answer (Yes,No,N/A) | J4: Comments
C5: A.공급사 평가및 검증 | E5: 1 | G5: 공급사는 PSA Busan의 공급사로써의 자격 요건을 갖추었는가? | H5: 자격 요건 1. PSA Busan 공급사의 요건으로써 최소 3년 이상의 해당 서비스(실물) 제공 경력이 3년 이상이거나, 또는 동종업계 경력 5년 이상 보유자를 임직원으로 보유 2. 공급사는 과거 3년간 PSA Busan의 사업에 손실이나 폐해를 끼친적이 없음
E6: 2 | G6: PSA Busan의 공급사가 되기 위한 정해진 검증(Qualification) 과정을 통과하고 입찰위원회의 승인을 득하였는가? | H6: 검증 항목 1. 회사 기본 정보 (Company Profile) - 회사 연혁, 경영진 정보, 사업 영역, 실적, 주요 고객 현 황 등 2. 재무 정보 - PSA Busan이 인정한 신용 평가 기관의 평가 등급 또는 최근 3개년 재무제표 또 는 세무 신고 내역 등 유동성 / 부채비율 / 영업이익율 등의 파악이 가능한 정보 3. 사업 정보 - 제공하는 실물 및 서비스에 대한 사업 특성 정보
E7: 3 | G7: 공급사의 자격 상실 요건을 충족하는 공급사에 대한 자격 상실 처리를 실시하고 있는가? | H7: 자격상실 요건 1. PSA Busan의 사업에 손실이나 폐해를 끼친 경우 (단, PSA Busan 사업에 손실이나 폐해를 끼 쳤을 경우라도 대표이사의 승인을 득한 경우 예외) 2. 재무 안정성이 저하되어 더 이상 안정적인 사업 관계가 성립되기 어렵다고 PSA Busan의 해당 사업부문에서 판단하는 경우 3. PSA Busan과의 사업 관계에 있어 관련 법령 위반을 통한 문제를 야기한 경우
E8: 4 | G8: 공급사 자격 상실 예외 Case에 대해 대표이사의 승인을 득하였는가?
E9: 5 | G9: 구매 Policy 적용 대상 공급사에 대한 평가를 실시하였는가?
C10: B.계약 관리 | E10: 1 | G10: 입찰이 성립하기 위해 복수의 공급사가 입찰에 참여하였는가?
F11: 1.1 | G11: 그렇지 않다면, Waiver에 대한 승인을 득하였는가?
E12: 2 | G12: 입찰 기본 요건이 충족되지 않은 경우, 재입찰이 실시되었는가? | H12: 재입찰 요건 1. 최소 입찰 공급사 입찰 참여하였을 경우 2. 입찰 과정에서 불법적이나 불합리한 점이 개입 되었음이 확인 되었을 경우
F13: 2.1 | G13: 그렇지 않다면, 입찰 기본 요건이 충족되지 않고, 재입찰도 불가능할 경우,예외 입찰(Exceptional bidding)에 대한 정당한 사유 및 구매 가격 타당성에 대한 검증 근거를 서면으로 작성하여 승인을 득하였는 가? | H13: 승인 절차에 필요한 문서 1. 예외 입찰이 허용디는 경우 입증 문서 2. 계약 또는 구매 하기로 결정한 가격이 가장 타당한 가격임을 입증하는 문서
E14: 3 | G14: 입찰 결과 관련 문서는 전자 문서 또는 기타 문서의 형태로 관리되고 있는가? | H14: 입찰 결과 관련 문서 1. 입찰공고문 2. 입찰 참여사 제출 제안서 및 기타 자료 3. 입찰위원 승인을 득한 입찰 참여사 제안서 4. 승인을 득한 입찰 평가서(TENDER EVALUATION) 5. 입찰 결과에 대한 공급사 회신 사항
E15: 4 | G15: 공급사 선정은 경쟁 입찰을 기본 원칙으로 하여 수행되었는가?
E16: 5 | G16: 그렇지 않다면, (경쟁 입찰이 불가능한 경우) 이에 대한 정당한 사유를 제시하고 대표이사의 승인을 득하였는가?
E17: 6 | G17: 공급사 선정하기 위한 타당한 평가 항목과 기준이 적용되었는가? | H17: 평가 항목 1. 실태 평가: 공급사 Profile, Capacity 정보, 재무안정성 평가, 서비스 영역 및 지역 정보 등 2. 실적 평가: 공급사와 PSA Busan과의 기 거래 실적 및 서비스 만족도, 전략적 중요도 평가 등 3. 가격 평가: 경쟁 입찰에 준하여 평가 평가항목 가중치 공급사 선정을 위한 평가 항목 및 기준, 평가 항목별 가중치는 구매 물품 및 서비스 특성에 따라 차별화 되어야 함
E18: 6.1 | G18: PSA Busan에 공급하는 인력에 대한 적격성을 검증하였는가? (PSA Busan 운영 관련 업무를 수행하는 외주업체 限) | H18: 평가 항목 1. 반장이상 : 적격성 검토서를 통한 적격성(능력, 스킬, 태도) 검증 2. 그외직원 : 공급사 자체 근무평가로 대체 평가항목 가중치 적격성 검증을 위한 평가 항목 및 기준, 평가 항목별 가중치는 업무별 특성에 따라 차별화 되어야 함
E19: 7 | G19: 계약 성립의 최소 요건인 기본 계약서를 체결하였는가?
E20: 8 | G20: 계약서의 유효 기간 및 갱신 주기는 1년을 기본 원칙으로 하고 있는가? | H20: 계약 유효 기간 및 갱신 주기는 1년을 기본으로 하되, 시장 상황과 시황에 따라 PSA Busan에게 유리하다고 판단되는 경우에는 기간을 조정할 수 있어야 함
E21: 9 | G21: PSA Busan에서 작성한 기본 계약서 양식 사용이 불가능할 경우, 타당한 사유를 작성하여 구매법무팀장 승인 하에 기본 계약 양식을 변형하여 사용하였는가? | H21: 이 경우 구매법무팀의 검수를 거쳐야 함
E22: 10 | G22: 복수 입찰 없이 동일 공급사와 계약 기간 연장을 위한 검증 및 승인 과정을 이행하였는가? | H22: 복수 입찰 없이 동일 공급사와 계약 기간을 연장하기 위해서는, 연장 계약하고자 하는 요율을 포함한 계약 조건이 해당 시기에 가장 최적의 것임을 규명하여야 함

Sheet Supplier Assessment
B1: Supplier Assessment
B3: 1.Supplier Capability Assessment
B5: Please fill-in below information.
B6: Supplier Capability
B7: 평가 항목 | C7: 평가 세부 구분 | D7: 가중치 | E7: Criteria | F7: No | G7: Score
B8: Financial Stability | C8: 재무현황 개선도 (전년도 대비) | D8: 0.05 | E8: 20% 이상 매출 상승 | F8: 4 | H8: 1 | I8: =((D8*G8)/4)*100 -> 0 | J8: =D8*100 -> 5
E9: 0~10% 매출 상승 | F9: 3
E10: 0~10% 매출 감소 | F10: 2
E11: 20% 이상 매출 감소 | F11: 1
B12: Company Certification | C12: ISO 인증 여부 | D12: 0.05 | E12: ISO 인증서 3개 이상 | F12: 4 | H12: =H8+1 -> 2 | I12: =((D12*G12)/4)*100 -> 0 | J12: =D12*100 -> 5
E13: ISO 인증서 2개 | F13: 3
E14: ISO 인증서 1개 | F14: 2
E15: 없음 | F15: 1
B16: Account Manger for PSA Busan | C16: 전담 조직 구성 | D16: 0.05 | E16: 전문인력으로 전담조직 구성 | F16: 4 | H16: =H12+1 -> 3 | I16: =((D16*G16)/4)*100 -> 0 | J16: =D16*100 -> 5
E17: 비전문인력으로 전담조직은 구성 | F17: 3
E18: 전담조직은 없으나 담당자 1인 지정 | F18: 2
E19: 담당자가 수시로 변경되며 인수인계 부정확 | F19: 1
B20: Historical Business Status | C20: 당사와의 거래이력 | D20: 0.05 | E20: 5년 이상 | F20: 4 | H20: =H16+1 -> 4 | I20: =((D20*G20)/4)*100 -> 0 | J20: =D20*100 -> 5
E21: 3년 이상 5년 미만 | F21: 3
E22: 1년 이상 3년 미만 | F22: 2
E23: 1년 미만 | F23: 1
F24: Total Score | G24: =SUMPRODUCT(D8:D23,G8:G23) -> 0
F25: Conversion | G25: =G24/4*100 -> 0
B27: 2.Supplier Performance Assessment
B28: Remarks: 구매 자재 업체의 경우 Price, Quality, Service Level & Delivery/Response를 기준으로 실적평가를 실시함
B29: Please fill-in below information.
B30: Supplier Performance
B31: 평가 항목 | C31: 평가 세부 구분 | D31: 가중치 | E31: Criteria | F31: No | G31: Score
B32: Price | C32: 원가절감율 (전체발주액 대비 할인액 비율) | D32: 0.2 | E32: 5% 이상 | F32: 4 | H32: =H20+1 -> 5 | I32: =((D32*G32)/4)*100 -> 0 | J32: =D32*100 -> 20
E33: 3~5% 미만 | F33: 3
E34: 3% 미만 | F34: 2
E35: 전혀없다 | F35: 1
B36: Quality | C36: 품질관리 | D36: 0.05 | E36: 품질관리 방식 및 실시상황이 매우 양호 | F36: 4 | H36: =H32+1 -> 6 | I36: =((D36*G36)/4)*100 -> 0 | J36: =D36*100 -> 5
E37: 품질관리 방식 및 실시상황이 양호 | F37: 3
E38: 품질관리 방식 및 실시상황이 미흡 | F38: 2
E39: 품질관리 방식 및 실시상황이 매우 미흡 | F39: 1
C40: CLAIM 발생 빈도 | D40: 0.05 | E40: 전체 발주건수대비 1% 미만 | F40: 4 | H40: =H36+1 -> 7 | I40: =((D40*G40)/4)*100 -> 0 | J40: =D40*100 -> 5
E41: 전체 발주건수대비 1% 이상 3% 미만 | F41: 3
E42: 전체 발주건수대비 3% 이상 5% 미만 | F42: 2
E43: 전체 발주건수대비 5% 이상 | F43: 1
...

Sheet Contractor Information
A1: Contractor List
A2: ABB
A3: No. | B3: LBU | C3: ABB Div. | D3: =HSE!A8 -> 회사명 | E3: =HSE!I8 -> 대표자 성명 | F3: 업종 | G3: 계약 내용 | H3: =HSE!I10 -> 거래 / 작업 예상 빈도(년) | I3: 직책 | J3: 연락처 | K3: E-Mail | L3: 평가점수
A4: 1 | B4: IAMP | C4: HSE | D4: =HSE!E8 -> 길동상사 | E4: =HSE!M8 -> 홍길돌 | F4: =HSE!U4 -> 제조업 | G4: 부품 조립 등 | H4: =HSE!M10 -> 0 | J4: =HSE!E9 -> 010-1234-5678 | K4: =HSE!U9 -> 0 | L4: =HSE!Z15 -> 100
A5: 2 | B5: IAMP
A6: 3 | B6: EP4P&IAMA
A7: 4 | B7: EP4P&IAMA
A8: 5 | B8: EP4P&IAMA
A9: 6 | B9: EP4P&IAMA
A10: 7 | B10: EP
A11: 8 | B11: EP
A12: 9 | B12: EP
A13: 10 | B13: EP
A14: 11 | B14: EP
A15: 12 | B15: EP
A16: 13 | B16: EP
... A103: 100 | B103: RM

Sheet HSE
A2: HSE 협력업체 평가표 (Contractor Qaulification Sheet)
A4: 날짜: | R4: 업 종 | U4: 제조업
A6: [일반사항]
A8: 회사명 | E8: 길동상사 | I8: 대표자 성명 | M8: 홍길돌 | Q8: 사업자등록번호
A9: 전화번호 | E9: 010-1234-5678 | I9: 팩스번호 | Q9: 이메일
A10: 본사주소지 | I10: 거래 / 작업 예상 빈도(년) | Q10: 근로자수
A12: [안전보건관리자 선임] 해당없을 경우 비워둘것
A14: 안전∙보건 관리책임자 | M14: 현장 책임자 | Z14: 평가점수
A15: 안전관리자 | M15: 보건관리자 | Z15: =SUM(AB20:AB76) -> 100 | AC15: 적격 수급업체 기준: 70점 이상
A17: [안전보건방침]
A19: NO. | B19: 질의내용 | J19: 답변 | O19: 체크 | P19: 내용 | U19: 증빙 | AA19: 점수
A20: 1 | B20: 귀사는 안전보건방침(안전보건절차서, 매뉴얼 등)이 수립되어 있습니까? | J20: 1. YES | O20: O | U20: 사본 제출 | Z20: =COUNTIF(O20,"O") -> 1 | AA20: 4 | AB20: =Z20*AA20 -> 4
J21: 2. NO | Z21: =COUNTIF(O21,"O") -> 0 | AA21: 0 | AB21: =Z21*AA21 -> 0
A22: 2 | B22: 귀사는 산업재해예방 활동에 대한 이행계획이 절적히 수립되었습니까? | J22: 1. YES | O22: O | U22: 사본 제출
J23: 2. NO
A24: 3 | B24: 귀사는 안전보건방침(안전보건관리체계 등) 이행계획 추진을 위한 역할이 분담되어 있습니까? | J24: 1. YES | O24: O | U24: 사본 제출 | Z24: =COUNTIF(O24,"O") -> 1 | AA24: 4 | AB24: =Z24*AA24 -> 4
J25: 2. NO | Z25: =COUNTIF(O25,"O") -> 0 | AA25: 0 | AB25: =Z25*AA25 -> 0
A26: 4 | B26: 귀사의 안전보건절차서에 비상시 대피 및 피해 최소화 대책히 포함되어 있습니까? | J26: 1. YES | O26: O | U26: 사본 제출 | Z26: =COUNTIF(O26,"O") -> 1 | AA26: 4 | AB26: =Z26*AA26 -> 4
J27: 2. NO | Z27: =COUNTIF(O27,"O") -> 0 | AA27: 0 | AB27: =Z27*AA27 -> 0
A28: 5 | B28: 귀사의 안전보건절차서에 유해위험물질 및 취급 기계,기구, 설비의 안정성 확인에 대한 매뉴얼이 적절히 수립되어 있습니까? | J28: 1. YES | O28: O | U28: 사본 제출 | Z28: =COUNTIF(O28,"O") -> 1 | AA28: 4 | AB28: =Z28*AA28 -> 4
J29: 2. NO | Z29: =COUNTIF(O29,"O") -> 0 | AA29: 0 | AB29: =Z29*AA29 -> 0
A30: 6 | B30: 귀사는 유해위험작업에 대해 작업허가서를 이행하고 있습니까? | J30: 1. YES | O30: O | U30: 사본 제출 | Z30: =COUNTIF(O30,"O") -> 1 | AA30: 4 | AB30: =Z30*AA30 -> 4
J31: 2. NO | Z31: =COUNTIF(O31,"O") -> 0 | AA31: 0 | AB31: =Z31*AA31 -> 0
A32: 7 | B32: 귀사의 안전보건절차서에 비상 시 및 사고발생 시 신호 및 연락체계가 수립되어 있습니까? | J32: 1. YES | O32: O | U32: 사본 제출 | Z32: =COUNTIF(O32,"O") -> 1 | AA32: 4 | AB32: =Z32*AA32 -> 4
J33: 2. NO | Z33: =COUNTIF(O33,"O") -> 0 | AA33: 0 | AB33: =Z33*AA33 -> 0
A34: 8 | B34: 귀사는 유해위험작업에 대해 위험성평가를 적절하게 시행하고 그 대책에 대해 이행을 하고 있습니까? | J34: 1. YES | O34: O | U34: 사본 제출 | Z34: =COUNTIF(O34,"O") -> 1 | AA34: 4 | AB34: =Z34*AA34 -> 4
J35: 2. NO | Z35: =COUNTIF(O35,"O") -> 0 | AA35: 0 | AB35: =Z35*AA35 -> 0
A37: [사고기록]
A39: 1 | B39: 귀사는 안전보건관련하여 시스템 인증이 있습니까? 또는 위험성 평가 인정을 받았습니까? * 100인 이상 : OHSAS/KOSHA 18001 * 100인 미만 : 위험성평가 인정 | J39: 1. 인증을 보유 | O39: O | U39: 인증서사본 제출요망 | Z39: =COUNTIF(O39,"O") -> 1 | AA39: 4 | AB39: =Z39*AA39 -> 4
J40: 2. 아직 없지만 1년 이내 받을 계획 | Z40: =COUNTIF(O40,"O") -> 0 | AA40: 4 | AB40: =Z40*AA40 -> 0
J41: 3. 향후 1년이내에 계획이 없음 | Z41: =COUNTIF(O41,"O") -> 0 | AA41: 0 | AB41: =Z41*AA41 -> 0
A42: 2 | B42: 귀사는 산업안전보건법 제 15조에 따라 안전관리자가 선임되어 있습니까? | J42: 1. YES | O42: O | U42: 해당 없을 경우 내용 기입 | Z42: =COUNTIF(O42,"O") -> 1 | AA42: 4 | AB42: =Z42*AA42 -> 4
J43: 2. NO | Z43: =COUNTIF(O43,"O") -> 0 | AA43: 0 | AB43: =Z43*AA43 -> 0
J44: 3. 해당 없음 | Z44: =COUNTIF(O44,"O") -> 0 | AA44: 4 | AB44: =Z44*AA44 -> 0
A45: 3 | B45: 귀사는 산업안전보건법 제 16조에 따라 보건관리자가 선임되어 있습니까? | J45: 1. YES | O45: O | U45: 해당 없을 경우 내용 기입 | Z45: =COUNTIF(O45,"O") -> 1 | AA45: 4 | AB45: =Z45*AA45 -> 4
J46: 2. NO | Z46: =COUNTIF(O46,"O") -> 0 | AA46: 0 | AB46: =Z46*AA46 -> 0
J47: 3. 해당 없음 | Z47: =COUNTIF(O47,"O") -> 0 | AA47: 4 | AB47: =Z47*AA47 -> 0
A49: [사고기록]
A51: NO. | B51: 질의내용 | J51: 답변 | O51: 체크 | P51: 내용 | U51: 증빙
A52: 1 | B52: 귀사는 지난 3년 동안에 중대재해가 발생되었습니까? | J52: 1. YES | U52: 안전보건공단 산업재해율 제출 | Z52: =COUNTIF(O52,"O") -> 0 | AA52: 0 | AB52: =Z52*AA52 -> 0
...

Sheet 첨부.5 신규 공급사 평가 및 점검
B1: <첨부 5> 신규 공급사 평가 및 점검(AEO 비관련사)
B3: 1.Supplier Capability Assessment
B5: Please fill-in below information.
B6: Supplier Capability
B7: 평가 항목 | C7: 평가 세부 구분 | D7: 가중치 | E7: Criteria | F7: No | G7: Score
B8: 전문성 | C8: 사업 영업기간 | D8: 0.15 | E8: 15년 | F8: 5
E9: 10년 | F9: 4
E10: 5년 | F10: 3
E11: 3년 | F11: 2
E12: 1년 | F12: 1
B13: 재무건전성 | C13: 유동비율 (유동자산 /유동부채)x100 | D13: 0.1 | E13: 200% ~ | F13: 5
E14: 180% ~ 200% | F14: 4
E15: 160% ~ 180% | F15: 3
E16: 140% ~ 160% | F16: 2
E17: 120% ~ 140% | F17: 1
C18: 부채비율 (부채총액/자기자본 x 100) | D18: 0.1 | E18: 0% ~ 200% | F18: 5
E19: 200% ~ 220% | F19: 4
E20: 220% ~ 240% | F20: 3
E21: 240% ~ 260% | F21: 2
E22: 260% ~ 280% | F22: 1
C23: 자기자본비율 (자기자본/총 자 산 x 100) | D23: 0.1 | E23: 8% ~ | F23: 5
E24: 7% | F24: 4
E25: 6% | F25: 3
E26: 5% | F26: 2
E27: 4% | F27: 1
B28: 대외신인도 | C28: 업계신용도 국내 외 계약업체 및 거래처의수 | D28: 0.15 | E28: 5개 이상 | F28: 5
E29: 4개 | F29: 4
E30: 3개 | F30: 3
E31: 2개 | F31: 2
E32: 1개 | F32: 1
B34: 평가 항목 | C34: 평가 세부 구분 | D34: 가중치 | E34: Criteria | F34: No | G34: Score
B35: 조직현황 | C35: 본점 및 현장 적정인원 | D35: 0.1 | E35: 여유 인원 확보 | F35: 5
E36: 업무특성에 맞게 적정인원 유지 | F36: 4
E37: 인원 부족 | F37: 0
C38: 업무경력 | D38: 0.15 | E38: 조직 구성원의 평균 근무년수 3년 이상 | F38: 5
E39: 조직 구성원의 평균 근무년수 1~2년 | F39: 3
E40: 1년 미만 | F40: 1
B41: 설비 및 장비 | C41: 적정설비 유지 | D41: 0.15 | E41: 운영을 위한 설비 장비 전체 보유 | F41: 5
E42: 필요 설비 및 장비 부족 1건 | F42: 4
E43: 필요 설비 및 장비 부족 2건 | F43: 3
...

Sheet Sheet1
D2: User Department
D3: Prepared by | F3: Reviewed by | H3: Reviewed by | J3: Approved by
B4: SIGNATURE
B6: NAME
